Workbook

Sheet 使い方
B2: 架電管理シート（MAKRH / 栃木県内）
B4: このシートについて
B5: 「架電リスト」タブに候補店を入力し、電話をかけた結果を記録していきます。
B6: 対象: 栃木県内の観光関連個人店（カフェ・飲食店・和菓子/雑貨店・陶器店/ギャラリー・土産店）＋ 美容室・理容室。
B7: 現在20市町にまたがる候補を掲載（栃木市・益子町・那須町・日光市を中心に、宇都宮市など主要都市にも拡大）。
B9: 500件を目指す上での注意
B10: このシートはWeb検索で見つけた実在店舗の下調べリストです。件数を大きく伸ばすには限界があり、
B11: 特に美容室・理容室は店舗数が非常に多い一方、Web検索の要約からは個別店名が拾いにくい業態です。
B12: 母数を一気に増やすには「iタウンページ」（https://itp.ne.jp/）で業種×市区町村を指定して検索・
B13: コピペする方法がもっとも効率的です（店名・電話番号・住所が一覧で出ます）。詳細は knowledge フォルダのメモ参照。
B15: 入力のしかた
B16: 黄色のセルは要確認・要入力です（電話番号・定休日など、Web検索だけでは確認できなかった項目）。
... B24: 「集計」タブに架電数・アポ率・市町別件数が自動計算されます（架電リストの入力に連動）。

Sheet 架電リスト
A1: No. | B1: 店名 | C1: 業種 | D1: 市町 | E1: 住所/場所 | F1: 電話番号 | G1: 定休日 | H1: 現状サイト有無 | I1: 情報源 | J1: 架電日 | K1: 結果 | L1: 次回アクション予定日 | M1: メモ
A2: 1 | B2: 舟見茶家 憩いどころ齋 | C2: カフェ | D2: 栃木市 | E2: 蔵の街エリア（巴波川沿い・古民家） | G2: 不明 | H2: 不明 | I2: 栃木市観光協会 掲載店 | K2: 未架電 | M2: 明治期の古民家を改装、蔵の街並みを一望できるカフェ
A3: 2 | B3: ハウディーズカフェ | C3: カフェ | D3: 栃木市 | E3: 小平町10-17 | G3: 不明 | H3: 不明 | I3: 観光メディア掲載店 | K3: 未架電 | M3: 古民家を改装したカフェ
A4: 3 | B4: 光明寺山門カフェ | C4: カフェ | D4: 栃木市 | E4: 蔵の街エリア（光明寺 山門付近） | G4: 不明 | H4: 不明 | I4: 観光メディア掲載店 | K4: 未架電 | M4: 蔵を使った小さなカフェ、ドリップコーヒー
A5: 4 | B5: 和菓子処 仁 | C5: 和菓子店 | D5: 栃木市 | E5: 蔵の街エリア | G5: 不明 | H5: 不明 | I5: グルメサイト掲載店 | K5: 未架電 | M5: 季節の創作和菓子
A6: 5 | B6: 蔵の菓 栃木本店 | C6: 和菓子店 | D6: 栃木市 | E6: 蔵の街エリア | G6: 不明 | H6: 不明 | I6: 地域情報サイト掲載店 | K6: 未架電 | M6: 石蔵をリノベーション、バームクーヘン等
A7: 6 | B7: 永井百貨店 | C7: 雑貨店 | D7: 栃木市 | E7: 蔵の街エリア | G7: 不明 | H7: 不明 | I7: 観光メディア掲載店 | K7: 未架電 | M7: 栃木・全国のお土産セレクトショップ
A8: 7 | B8: Feel hair face | C8: 美容室 | D8: 栃木市 | E8: 蔵の街大通り沿い（万町交番付近） | G8: 不明 | H8: 不明 | I8: 電話帳サイト掲載店 | K8: 未架電
A9: 8 | B9: 美容室エミュ 蔵の街店 | C9: 美容室 | D9: 栃木市 | E9: 富士見町5-32 | G9: 不明 | H9: 不明 | I9: 地域情報サイト掲載店 | K9: 未架電
A10: 9 | B10: やまに大塚 | C10: 陶器店・ギャラリー | D10: 益子町 | E10: 城内坂エリア | G10: 不明 | H10: 不明 | I10: 公式サイト | K10: 未架電 | M10: 益子焼ギャラリー・カフェ・陶芸教室を併設
A11: 10 | B11: 益子焼窯元 つかもと | C11: 陶器店・ギャラリー | D11: 益子町 | E11: 城内坂通り | G11: 不明 | H11: 不明 | I11: 観光メディア掲載店 | K11: 未架電 | M11: ギャラリー・カフェ・レストラン併設
A12: 11 | B12: tete+gallery | C12: 陶器店・ギャラリー | D12: 益子町 | E12: 益子駅〜城内坂の途中 | G12: 不明 | H12: 不明 | I12: 観光メディア掲載店 | K12: 未架電 | M12: 作家本人が制作する陶器ギャラリー
A13: 12 | B13: 益子の茶屋（窯元よこやま） | C13: カフェ | D13: 益子町 | E13: 城内坂エリア | G13: 不明 | H13: 不明 | I13: 公式サイト | K13: 未架電 | M13: 益子焼の器で提供する陶芸カフェレストラン
A14: 13 | B14: 古民家のカフェ 夢屋 | C14: カフェ | D14: 那須町 | E14: 那須高原（森の中） | G14: 不明 | H14: 不明 | I14: 観光メディア掲載店 | K14: 未架電 | M14: 古民家を改装したカフェ
A15: 14 | B15: craft&design WHITE NOTE | C15: 雑貨店 | D15: 那須町 | E15: 那須高原 | G15: 不明 | H15: 不明 | I15: 観光メディア掲載店 | K15: 未架電 | M15: 生活道具・手作り雑貨の店
A16: 15 | B16: ペニー・レイン 那須店 | C16: カフェ | D16: 那須町 | E16: 那須高原 | G16: 不明 | H16: 不明 | I16: 観光メディア掲載店 | K16: 未架電
A17: 16 | B17: NASU SHOZO CAFE | C17: カフェ | D17: 那須町 | E17: 那須高原 | G17: 不明 | H17: 不明 | I17: 観光メディア掲載店 | K17: 未架電
A18: 17 | B18: Cafe La Detente（自家焙煎 那須珈琲） | C18: カフェ | D18: 那須町 | E18: 那須高原 | G18: 不明 | H18: 不明 | I18: 観光メディア掲載店 | K18: 未架電 | M18: 自家焙煎コーヒーの店
A19: 18 | B19: Cafe St.Croix | C19: カフェ | D19: 那須町 | E19: 那須高原 | G19: 不明 | H19: 不明 | I19: 観光メディア掲載店 | K19: 未架電 | M19: 薪ストーブと珈琲の店
A20: 19 | B20: 本宮カフェ | C20: カフェ | D20: 日光市 | E20: 山内2384 | G20: 不明 | H20: 不明 | I20: 観光メディア掲載店 | K20: 未架電 | M20: 築330余年の古民家カフェ
A21: 20 | B21: 湯沢屋直営カフェ | C21: 和菓子店 | D21: 日光市 | E21: 日光東照宮 参道エリア | G21: 不明 | H21: 不明 | I21: 観光メディア掲載店 | K21: 未架電 | M21: 明治創業の老舗和菓子店直営、湯波料理も提供
A22: 21 | B22: さかえや | C22: 土産店 | D22: 日光市 | E22: 東武日光駅前 | G22: 不明 | H22: 不明 | I22: 観光メディア掲載店 | K22: 未架電 | M22: 創業60年以上、揚げゆばまんじゅうが名物
A23: 22 | B23: 油源 | C23: 土産店 | D23: 日光市 | E23: 日光東照宮周辺 | G23: 不明 | H23: 不明 | I23: 観光メディア掲載店 | K23: 未架電 | M23: 1859年創業の老舗
A24: 23 | B24: 宇都宮みんみん 本店 | C24: 飲食店 | D24: 宇都宮市 | E24: 宇都宮駅前エリア | G24: 不明 | H24: 不明 | I24: 観光メディア掲載店 | K24: 未架電 | M24: 昭和33年創業の老舗餃子専門店
A25: 24 | B25: 正嗣 宮島本店 | C25: 飲食店 | D25: 宇都宮市 | E25: 宮島町 | G25: 不明 | H25: 不明 | I25: 観光メディア掲載店 | K25: 未架電 | M25: 昭和40年創業、焼餃子と水餃子のみの専門店
A26: 25 | B26: 香蘭 | C26: 飲食店 | D26: 宇都宮市 | E26: 宇都宮駅前 | G26: 不明 | H26: 不明 | I26: 公式サイト | K26: 未架電 | M26: 創業昭和34年の老舗餃子店
A27: 26 | B27: 青源 | C27: 飲食店 | D27: 宇都宮市 | G27: 不明 | H27: 不明 | I27: 観光メディア掲載店 | K27: 未架電 | M27: 創業300年以上の老舗味噌屋が手がける餃子店
A28: 27 | B28: かふえあんでぃーぶ | C28: カフェ | D28: 足利市 | G28: 不明 | H28: 不明 | I28: 観光メディア掲載店 | K28: 未架電 | M28: 老舗カフェ、ドリップコーヒー
A29: 28 | B29: 珈琲蔵 | C29: カフェ | D29: 足利市 | G29: 不明 | H29: 不明 | I29: 観光メディア掲載店 | K29: 未架電 | M29: 蔵を改装した喫茶店
A30: 29 | B30: 八蔵（はちくら） | C30: カフェ | D30: 足利市 | E30: 足利駅南口徒歩8分・石畳通り | G30: 不明 | H30: 不明 | I30: 観光メディア掲載店 | K30: 未架電 | M30: 米蔵をリノベーションした古民家カフェ
A31: 30 | B31: 茶房のの | C31: カフェ | D31: 足利市 | E31: 八幡町 | G31: 不明 | H31: 不明 | I31: 公式サイト | K31: 未架電 | M31: 古民家カフェ、あんみつ・かき氷
A32: 31 | B32: 麺や 大山 | C32: 飲食店 | D32: 佐野市 | G32: 不明 | H32: 不明 | I32: グルメサイト掲載店 | K32: 未架電 | M32: 佐野ラーメンの名店、青竹手打ち麺
A33: 32 | B33: 麺屋ようすけ | C33: 飲食店 | D33: 佐野市 | G33: 不明 | H33: 不明 | I33: グルメサイト掲載店 | K33: 未架電 | M33: 佐野ラーメン、透き通るスープ
A34: 33 | B34: 森田屋総本店 | C34: 飲食店 | D34: 佐野市 | G34: 不明 | H34: 不明 | I34: グルメサイト掲載店 | K34: 未架電 | M34: 佐野ラーメン、麺・チャーシュー・スープ全て自家製
A35: 34 | B35: クラシック・カフェ音楽館 | C35: カフェ | D35: 小山市 | E35: 犬塚5丁目 | G35: 不明 | H35: 不明 | I35: グルメサイト掲載店 | K35: 未架電 | M35: 古民家、クラシック音楽が流れる店内
A36: 35 | B36: だんご茶屋 | C36: 和菓子店 | D36: 小山市 | E36: 小山第二中学校付近 | G36: 不明 | H36: 不明 | I36: グルメサイト掲載店 | K36: 未架電 | M36: 白玉ぜんざいなど
A37: 36 | B37: 居場所カフェ・あおぞら | C37: カフェ | D37: 小山市 | G37: 不明 | H37: 不明 | I37: グルメサイト掲載店 | K37: 未架電 | M37: 無農薬野菜を使った健康志向カフェ
A38: 37 | B38: CafeQ | C38: カフェ | D38: 小山市 | E38: 城東 | G38: 不明 | H38: 不明 | I38: グルメサイト掲載店 | K38: 未架電 | M38: 山小屋風、ハンバーガーが名物
A39: 38 | B39: Bee House | C39: カフェ | D39: 小山市 | E39: 国道50号沿い | G39: 不明 | H39: 不明 | I39: グルメサイト掲載店 | K39: 未架電 | M39: ホットケーキが名物
A40: 39 | B40: みやいりそば | C40: 飲食店 | D40: 鹿沼市 | E40: 深程1386-1 | G40: 月曜日 | H40: 不明 | I40: グルメサイト掲載店 | K40: 未架電 | M40: 鹿沼名物ニラそば、定休日: 月曜（要再確認）
...

Sheet 集計
B2: 週次集計
B4: 登録店舗数（合計） | D4: =COUNTIF(架電リスト!B2:B146,"?*")
B5: 架電済み件数 | D5: =COUNTIFS(架電リスト!K2:K146,"<>未架電",架電リスト!K2:K146,"<>")
B6: 資料送付OK件数 | D6: =COUNTIF(架電リスト!K2:K146,"資料送付OK")
B7: アポ確定件数 | D7: =COUNTIF(架電リスト!K2:K146,"アポ確定")
B8: アポ率（アポ確定 ÷ 架電済み） | D8: =IFERROR(D7/D5,0)
B10: 市町別 登録件数
B11: 栃木市 | D11: =COUNTIF(架電リスト!D2:D146,"栃木市")
B12: 益子町 | D12: =COUNTIF(架電リスト!D2:D146,"益子町")
B13: 那須町 | D13: =COUNTIF(架電リスト!D2:D146,"那須町")
B14: 日光市 | D14: =COUNTIF(架電リスト!D2:D146,"日光市")
B15: 宇都宮市 | D15: =COUNTIF(架電リスト!D2:D146,"宇都宮市")
B16: 足利市 | D16: =COUNTIF(架電リスト!D2:D146,"足利市")
B17: 佐野市 | D17: =COUNTIF(架電リスト!D2:D146,"佐野市")
B18: 小山市 | D18: =COUNTIF(架電リスト!D2:D146,"小山市")
B19: 鹿沼市 | D19: =COUNTIF(架電リスト!D2:D146,"鹿沼市")
B20: 那須塩原市 | D20: =COUNTIF(架電リスト!D2:D146,"那須塩原市")
B21: 真岡市 | D21: =COUNTIF(架電リスト!D2:D146,"真岡市")
B22: 大田原市 | D22: =COUNTIF(架電リスト!D2:D146,"大田原市")
B23: 壬生町 | D23: =COUNTIF(架電リスト!D2:D146,"壬生町")
B24: 那珂川町 | D24: =COUNTIF(架電リスト!D2:D146,"那珂川町")
B25: 那須烏山市 | D25: =COUNTIF(架電リスト!D2:D146,"那須烏山市")
B26: 矢板市 | D26: =COUNTIF(架電リスト!D2:D146,"矢板市")
B27: 茂木町 | D27: =COUNTIF(架電リスト!D2:D146,"茂木町")
B28: 下野市 | D28: =COUNTIF(架電リスト!D2:D146,"下野市")
B29: 野木町 | D29: =COUNTIF(架電リスト!D2:D146,"野木町")
B30: 高根沢町 | D30: =COUNTIF(架電リスト!D2:D146,"高根沢町")
B31: 芳賀町 | D31: =COUNTIF(架電リスト!D2:D146,"芳賀町")
B32: 塩谷町 | D32: =COUNTIF(架電リスト!D2:D146,"塩谷町")
B33: さくら市 | D33: =COUNTIF(架電リスト!D2:D146,"さくら市")
B34: 上三川町 | D34: =COUNTIF(架電リスト!D2:D146,"上三川町")
